2022-05-13 03:57:59,606:INFO:Initializing predict_model()
2022-05-13 03:57:59,607:INFO:predict_model(estimator=['Breed' 'Age' 'Sex' 'Symptoms'], probability_threshold=None, encoded_labels=False, drift_report=False, raw_score=False, round=4, verbose=True, ml_usecase=MLUsecase.CLASSIFICATION, display=None, drift_kwargs=None)
2022-05-13 03:57:59,607:INFO:Checking exceptions
2022-05-13 03:57:59,607:INFO:Preloading libraries
2022-05-13 03:57:59,607:ERROR:Pipeline not found. Exception:
2022-05-13 03:57:59,611:ERROR:Traceback (most recent call last):
  File "/Users/kimzio/opt/anaconda3/envs/capstone/lib/python3.7/site-packages/pycaret/internal/tabular.py", line 9044, in predict_model
    dtypes = prep_pipe.named_steps["dtypes"]
NameError: name 'prep_pipe' is not defined

2022-05-13 04:01:11,873:INFO:Initializing predict_model()
2022-05-13 04:01:11,874:INFO:predict_model(estimator=['Breed' 'Age' 'Sex' 'Symptoms'], probability_threshold=None, encoded_labels=False, drift_report=False, raw_score=False, round=4, verbose=True, ml_usecase=MLUsecase.CLASSIFICATION, display=None, drift_kwargs=None)
2022-05-13 04:01:11,874:INFO:Checking exceptions
2022-05-13 04:01:11,874:INFO:Preloading libraries
2022-05-13 04:01:11,874:ERROR:Pipeline not found. Exception:
2022-05-13 04:01:11,880:ERROR:Traceback (most recent call last):
  File "/Users/kimzio/opt/anaconda3/envs/capstone/lib/python3.7/site-packages/pycaret/internal/tabular.py", line 9044, in predict_model
    dtypes = prep_pipe.named_steps["dtypes"]
NameError: name 'prep_pipe' is not defined

2022-05-13 04:02:37,467:INFO:Initializing predict_model()
2022-05-13 04:02:37,467:INFO:predict_model(estimator=['Breed' 'Age' 'Sex' 'Symptoms'], probability_threshold=None, encoded_labels=False, drift_report=False, raw_score=False, round=4, verbose=True, ml_usecase=MLUsecase.CLASSIFICATION, display=None, drift_kwargs=None)
2022-05-13 04:02:37,467:INFO:Checking exceptions
2022-05-13 04:02:37,467:INFO:Preloading libraries
2022-05-13 04:02:37,467:ERROR:Pipeline not found. Exception:
2022-05-13 04:02:37,472:ERROR:Traceback (most recent call last):
  File "/Users/kimzio/opt/anaconda3/envs/capstone/lib/python3.7/site-packages/pycaret/internal/tabular.py", line 9044, in predict_model
    dtypes = prep_pipe.named_steps["dtypes"]
NameError: name 'prep_pipe' is not defined

2022-05-13 19:23:08,413:INFO:Initializing predict_model()
2022-05-13 19:23:08,414:INFO:predict_model(estimator=['Breed' 'Age' 'Sex' 'Symptoms'], probability_threshold=None, encoded_labels=False, drift_report=False, raw_score=False, round=4, verbose=True, ml_usecase=MLUsecase.CLASSIFICATION, display=None, drift_kwargs=None)
2022-05-13 19:23:08,414:INFO:Checking exceptions
2022-05-13 19:23:08,414:INFO:Preloading libraries
2022-05-13 19:23:08,414:ERROR:Pipeline not found. Exception:
2022-05-13 19:23:08,419:ERROR:Traceback (most recent call last):
  File "/Users/kimzio/opt/anaconda3/envs/capstone/lib/python3.7/site-packages/pycaret/internal/tabular.py", line 9044, in predict_model
    dtypes = prep_pipe.named_steps["dtypes"]
NameError: name 'prep_pipe' is not defined

2022-05-13 19:46:58,553:INFO:Initializing predict_model()
2022-05-13 19:46:58,555:INFO:predict_model(estimator=['Breed' 'Age' 'Sex' 'Symptoms'], probability_threshold=None, encoded_labels=False, drift_report=False, raw_score=False, round=4, verbose=True, ml_usecase=MLUsecase.CLASSIFICATION, display=None, drift_kwargs=None)
2022-05-13 19:46:58,555:INFO:Checking exceptions
2022-05-13 19:46:58,555:INFO:Preloading libraries
2022-05-13 19:46:58,557:ERROR:Pipeline not found. Exception:
2022-05-13 19:46:58,563:ERROR:Traceback (most recent call last):
  File "/Users/kimzio/opt/anaconda3/envs/capstone/lib/python3.7/site-packages/pycaret/internal/tabular.py", line 9044, in predict_model
    dtypes = prep_pipe.named_steps["dtypes"]
NameError: name 'prep_pipe' is not defined

2022-05-13 19:47:02,775:INFO:Initializing predict_model()
2022-05-13 19:47:02,776:INFO:predict_model(estimator=['Breed' 'Age' 'Sex' 'Symptoms'], probability_threshold=None, encoded_labels=False, drift_report=False, raw_score=False, round=4, verbose=True, ml_usecase=MLUsecase.CLASSIFICATION, display=None, drift_kwargs=None)
2022-05-13 19:47:02,776:INFO:Checking exceptions
2022-05-13 19:47:02,776:INFO:Preloading libraries
2022-05-13 19:47:02,776:ERROR:Pipeline not found. Exception:
2022-05-13 19:47:02,777:ERROR:Traceback (most recent call last):
  File "/Users/kimzio/opt/anaconda3/envs/capstone/lib/python3.7/site-packages/pycaret/internal/tabular.py", line 9044, in predict_model
    dtypes = prep_pipe.named_steps["dtypes"]
NameError: name 'prep_pipe' is not defined

2022-05-13 20:00:58,031:INFO:Initializing predict_model()
2022-05-13 20:00:58,031:INFO:predict_model(estimator=['Breed' 'Age' 'Sex' 'Symptoms'], probability_threshold=None, encoded_labels=False, drift_report=False, raw_score=False, round=4, verbose=True, ml_usecase=MLUsecase.CLASSIFICATION, display=None, drift_kwargs=None)
2022-05-13 20:00:58,031:INFO:Checking exceptions
2022-05-13 20:00:58,032:INFO:Preloading libraries
2022-05-13 20:00:58,032:ERROR:Pipeline not found. Exception:
2022-05-13 20:00:58,039:ERROR:Traceback (most recent call last):
  File "/Users/kimzio/opt/anaconda3/envs/capstone/lib/python3.7/site-packages/pycaret/internal/tabular.py", line 9044, in predict_model
    dtypes = prep_pipe.named_steps["dtypes"]
NameError: name 'prep_pipe' is not defined

2022-05-13 20:01:19,712:INFO:Initializing predict_model()
2022-05-13 20:01:19,712:INFO:predict_model(estimator=['Breed' 'Age' 'Sex' 'Symptoms'], probability_threshold=None, encoded_labels=False, drift_report=False, raw_score=False, round=4, verbose=True, ml_usecase=MLUsecase.CLASSIFICATION, display=None, drift_kwargs=None)
2022-05-13 20:01:19,712:INFO:Checking exceptions
2022-05-13 20:01:19,713:INFO:Preloading libraries
2022-05-13 20:01:19,713:ERROR:Pipeline not found. Exception:
2022-05-13 20:01:19,713:ERROR:Traceback (most recent call last):
  File "/Users/kimzio/opt/anaconda3/envs/capstone/lib/python3.7/site-packages/pycaret/internal/tabular.py", line 9044, in predict_model
    dtypes = prep_pipe.named_steps["dtypes"]
NameError: name 'prep_pipe' is not defined

2022-05-13 20:07:47,587:INFO:Initializing predict_model()
2022-05-13 20:07:47,587:INFO:predict_model(estimator=['Breed' 'Age' 'Sex' 'Symptoms'], probability_threshold=None, encoded_labels=False, drift_report=False, raw_score=False, round=4, verbose=True, ml_usecase=MLUsecase.CLASSIFICATION, display=None, drift_kwargs=None)
2022-05-13 20:07:47,587:INFO:Checking exceptions
2022-05-13 20:07:47,588:INFO:Preloading libraries
2022-05-13 20:07:47,588:ERROR:Pipeline not found. Exception:
2022-05-13 20:07:47,588:ERROR:Traceback (most recent call last):
  File "/Users/kimzio/opt/anaconda3/envs/capstone/lib/python3.7/site-packages/pycaret/internal/tabular.py", line 9044, in predict_model
    dtypes = prep_pipe.named_steps["dtypes"]
NameError: name 'prep_pipe' is not defined

2022-05-13 20:08:54,894:INFO:Initializing predict_model()
2022-05-13 20:08:54,895:INFO:predict_model(estimator=['Breed' 'Age' 'Sex' 'Symptoms'], probability_threshold=None, encoded_labels=False, drift_report=False, raw_score=False, round=4, verbose=True, ml_usecase=MLUsecase.CLASSIFICATION, display=None, drift_kwargs=None)
2022-05-13 20:08:54,895:INFO:Checking exceptions
2022-05-13 20:08:54,895:INFO:Preloading libraries
2022-05-13 20:08:54,895:ERROR:Pipeline not found. Exception:
2022-05-13 20:08:54,895:ERROR:Traceback (most recent call last):
  File "/Users/kimzio/opt/anaconda3/envs/capstone/lib/python3.7/site-packages/pycaret/internal/tabular.py", line 9044, in predict_model
    dtypes = prep_pipe.named_steps["dtypes"]
NameError: name 'prep_pipe' is not defined

2022-05-13 20:09:40,760:INFO:Initializing predict_model()
2022-05-13 20:09:40,761:INFO:predict_model(estimator=['Breed' 'Age' 'Sex' 'Symptoms'], probability_threshold=None, encoded_labels=False, drift_report=False, raw_score=False, round=4, verbose=True, ml_usecase=MLUsecase.CLASSIFICATION, display=None, drift_kwargs=None)
2022-05-13 20:09:40,761:INFO:Checking exceptions
2022-05-13 20:09:40,761:INFO:Preloading libraries
2022-05-13 20:09:40,762:ERROR:Pipeline not found. Exception:
2022-05-13 20:09:40,767:ERROR:Traceback (most recent call last):
  File "/Users/kimzio/opt/anaconda3/envs/capstone/lib/python3.7/site-packages/pycaret/internal/tabular.py", line 9044, in predict_model
    dtypes = prep_pipe.named_steps["dtypes"]
NameError: name 'prep_pipe' is not defined

2022-05-13 20:09:54,885:INFO:Initializing predict_model()
2022-05-13 20:09:54,885:INFO:predict_model(estimator=['Breed' 'Age' 'Sex' 'Symptoms'], probability_threshold=None, encoded_labels=False, drift_report=False, raw_score=False, round=4, verbose=True, ml_usecase=MLUsecase.CLASSIFICATION, display=None, drift_kwargs=None)
2022-05-13 20:09:54,885:INFO:Checking exceptions
2022-05-13 20:09:54,885:INFO:Preloading libraries
2022-05-13 20:09:54,885:ERROR:Pipeline not found. Exception:
2022-05-13 20:09:54,886:ERROR:Traceback (most recent call last):
  File "/Users/kimzio/opt/anaconda3/envs/capstone/lib/python3.7/site-packages/pycaret/internal/tabular.py", line 9044, in predict_model
    dtypes = prep_pipe.named_steps["dtypes"]
NameError: name 'prep_pipe' is not defined

2022-05-13 20:11:43,503:INFO:Initializing predict_model()
2022-05-13 20:11:43,504:INFO:predict_model(estimator=['Breed' 'Age' 'Sex' 'Symptoms'], probability_threshold=None, encoded_labels=False, drift_report=False, raw_score=False, round=4, verbose=True, ml_usecase=MLUsecase.CLASSIFICATION, display=None, drift_kwargs=None)
2022-05-13 20:11:43,504:INFO:Checking exceptions
2022-05-13 20:11:43,504:INFO:Preloading libraries
2022-05-13 20:11:43,504:ERROR:Pipeline not found. Exception:
2022-05-13 20:11:43,510:ERROR:Traceback (most recent call last):
  File "/Users/kimzio/opt/anaconda3/envs/capstone/lib/python3.7/site-packages/pycaret/internal/tabular.py", line 9044, in predict_model
    dtypes = prep_pipe.named_steps["dtypes"]
NameError: name 'prep_pipe' is not defined

2022-05-13 20:21:58,389:INFO:Initializing predict_model()
2022-05-13 20:21:58,390:INFO:predict_model(estimator=['Breed' 'Age' 'Sex' 'Symptoms'], probability_threshold=None, encoded_labels=False, drift_report=False, raw_score=False, round=4, verbose=True, ml_usecase=MLUsecase.CLASSIFICATION, display=None, drift_kwargs=None)
2022-05-13 20:21:58,390:INFO:Checking exceptions
2022-05-13 20:21:58,390:INFO:Preloading libraries
2022-05-13 20:21:58,390:ERROR:Pipeline not found. Exception:
2022-05-13 20:21:58,395:ERROR:Traceback (most recent call last):
  File "/Users/kimzio/opt/anaconda3/envs/capstone/lib/python3.7/site-packages/pycaret/internal/tabular.py", line 9044, in predict_model
    dtypes = prep_pipe.named_steps["dtypes"]
NameError: name 'prep_pipe' is not defined

2022-05-13 20:30:31,070:INFO:Initializing load_model()
2022-05-13 20:30:31,070:INFO:load_model(model_name=model/model_pipeline.pkl, platform=None, authentication=None, verbose=True)
2022-05-13 20:31:16,234:INFO:Initializing load_model()
2022-05-13 20:31:16,235:INFO:load_model(model_name=model/model_pipeline, platform=None, authentication=None, verbose=True)
2022-05-13 20:31:35,547:INFO:Initializing predict_model()
2022-05-13 20:31:35,547:INFO:predict_model(estimator=Pipeline(steps=[('dtypes',
                 DataTypes_Auto_infer(categorical_features=['Breed', 'Sex',
                                                            'Symptoms'],
                                      ml_usecase='classification',
                                      target='ICD')),
                ('imputer',
                 Simple_Imputer(categorical_strategy='not_available',
                                fill_value_categorical=None,
                                fill_value_numerical=None,
                                numeric_strategy='mean',
                                target_variable=None)),
                ('new_levels1',
                 New_Catagorical_Levels_in_TestDat...
                ('binn', 'passthrough'), ('rem_outliers', 'passthrough'),
                ('cluster_all', 'passthrough'),
                ('dummy', Dummify(target='ICD')),
                ('fix_perfect', Remove_100(target='ICD')),
                ('clean_names', Clean_Colum_Names()),
                ('feature_select', 'passthrough'), ('fix_multi', 'passthrough'),
                ('dfs', 'passthrough'), ('pca', 'passthrough'),
                ['trained_model', RidgeClassifier(random_state=2197)]]), probability_threshold=None, encoded_labels=False, drift_report=False, raw_score=False, round=4, verbose=True, ml_usecase=MLUsecase.CLASSIFICATION, display=None, drift_kwargs=None)
2022-05-13 20:31:35,547:INFO:Checking exceptions
2022-05-13 20:31:35,547:INFO:Preloading libraries
